from app.schemas.user_schema import UserAuth
from app.models.user_model import User
from app.core.security import get_password, verify_password
from typing import Optional

from uuid import UUID
import pymongo
from app.schemas.user_schema import UserUpdate

# todo arreglar el bug en user_in.save() -> user.py
class UserService:
    @staticmethod
    async def create_user(user: UserAuth):
        user_in = User(
            username=user.username,
            email=user.email,
            hashed_password=get_password(user.password)
        )
        await user_in.save()
        return user_in
    @staticmethod
    async def authenticate(email: str, password: str) -> Optional[User]:
        user = await UserService.get_user_by_email(email=email)
        if not user:    #si no existe un usuario con el email como parametro
            return None
        if not verify_password(password=password, hashed_pass=user.hashed_password):    #si el password es incorrecto
            return None
        
        return user
    
    @staticmethod
    async def get_user_by_email(email: str) -> Optional[User]:
        user = await User.find_one(User.email == email)
        return user
    
    @staticmethod
    async def get_user_by_id(id: UUID) -> Optional[User]:
        user = await User.find_one(User.user_id == id)
        return user
    
    @staticmethod
    async def update_user(id: UUID, data: UserUpdate) -> User:
        user = await User.find_one(User.user_id == id)
        if not user:
            raise pymongo.errors.OperationFailure("User not found")
    
        await user.update({"$set": data.dict(exclude_unset=True)})
        return user